2018-04-03 09:07:05,016 INFO: Microblog start up [in C:\Users\Wilson Wang\Desktop\Flask\microblog\app\__init__.py:43]
2018-04-03 09:07:28,282 ERROR: Exception on /edit_profile [POST] [in d:\python2.7\lib\site-packages\flask\app.py:1560]
Traceback (most recent call last):
  File "d:\python2.7\lib\site-packages\flask\app.py", line 1982, in wsgi_app
    response = self.full_dispatch_request()
  File "d:\python2.7\lib\site-packages\flask\app.py", line 1614, in full_dispatch_request
    rv = self.handle_user_exception(e)
  File "d:\python2.7\lib\site-packages\flask\app.py", line 1517, in handle_user_exception
    reraise(exc_type, exc_value, tb)
  File "d:\python2.7\lib\site-packages\flask\app.py", line 1612, in full_dispatch_request
    rv = self.dispatch_request()
  File "d:\python2.7\lib\site-packages\flask\app.py", line 1598, in dispatch_request
    return self.view_functions[rule.endpoint](**req.view_args)
  File "d:\python2.7\lib\site-packages\flask_login.py", line 792, in decorated_view
    return func(*args, **kwargs)
  File "C:\Users\Wilson Wang\Desktop\Flask\microblog\app\routes.py", line 85, in edit_profile
    db.session.commit()
  File "d:\python2.7\lib\site-packages\sqlalchemy\orm\scoping.py", line 153, in do
    return getattr(self.registry(), name)(*args, **kwargs)
  File "d:\python2.7\lib\site-packages\sqlalchemy\orm\session.py", line 943, in commit
    self.transaction.commit()
  File "d:\python2.7\lib\site-packages\sqlalchemy\orm\session.py", line 467, in commit
    self._prepare_impl()
  File "d:\python2.7\lib\site-packages\sqlalchemy\orm\session.py", line 447, in _prepare_impl
    self.session.flush()
  File "d:\python2.7\lib\site-packages\sqlalchemy\orm\session.py", line 2254, in flush
    self._flush(objects)
  File "d:\python2.7\lib\site-packages\sqlalchemy\orm\session.py", line 2380, in _flush
    transaction.rollback(_capture_exception=True)
  File "d:\python2.7\lib\site-packages\sqlalchemy\util\langhelpers.py", line 66, in __exit__
    compat.reraise(exc_type, exc_value, exc_tb)
  File "d:\python2.7\lib\site-packages\sqlalchemy\orm\session.py", line 2344, in _flush
    flush_context.execute()
  File "d:\python2.7\lib\site-packages\sqlalchemy\orm\unitofwork.py", line 391, in execute
    rec.execute(self)
  File "d:\python2.7\lib\site-packages\sqlalchemy\orm\unitofwork.py", line 556, in execute
    uow
  File "d:\python2.7\lib\site-packages\sqlalchemy\orm\persistence.py", line 177, in save_obj
    mapper, table, update)
  File "d:\python2.7\lib\site-packages\sqlalchemy\orm\persistence.py", line 768, in _emit_update_statements
    execute(statement, multiparams)
  File "d:\python2.7\lib\site-packages\sqlalchemy\engine\base.py", line 948, in execute
    return meth(self, multiparams, params)
  File "d:\python2.7\lib\site-packages\sqlalchemy\sql\elements.py", line 269, in _execute_on_connection
    return connection._execute_clauseelement(self, multiparams, params)
  File "d:\python2.7\lib\site-packages\sqlalchemy\engine\base.py", line 1060, in _execute_clauseelement
    compiled_sql, distilled_params
  File "d:\python2.7\lib\site-packages\sqlalchemy\engine\base.py", line 1200, in _execute_context
    context)
  File "d:\python2.7\lib\site-packages\sqlalchemy\engine\base.py", line 1413, in _handle_dbapi_exception
    exc_info
  File "d:\python2.7\lib\site-packages\sqlalchemy\util\compat.py", line 203, in raise_from_cause
    reraise(type(exception), exception, tb=exc_tb, cause=cause)
  File "d:\python2.7\lib\site-packages\sqlalchemy\engine\base.py", line 1193, in _execute_context
    context)
  File "d:\python2.7\lib\site-packages\sqlalchemy\engine\default.py", line 507, in do_execute
    cursor.execute(statement, parameters)
IntegrityError: (sqlite3.IntegrityError) UNIQUE constraint failed: user.username [SQL: u'UPDATE user SET username=?, about_me=? WHERE user.id = ?'] [parameters: (u'changshu', u'Student from Imperial College London, major in Electrical and Electronic Engineering!', 2)] (Background on this error at: http://sqlalche.me/e/gkpj)
2018-04-03 09:10:50,328 INFO: Microblog start up [in C:\Users\Wilson Wang\Desktop\Flask\microblog\app\__init__.py:43]
2018-04-03 09:16:21,111 INFO: Microblog start up [in C:\Users\Wilson Wang\Desktop\Flask\microblog\app\__init__.py:43]
2018-04-03 09:16:31,892 ERROR: Exception on /edit_profile [POST] [in d:\python2.7\lib\site-packages\flask\app.py:1560]
Traceback (most recent call last):
  File "d:\python2.7\lib\site-packages\flask\app.py", line 1982, in wsgi_app
    response = self.full_dispatch_request()
  File "d:\python2.7\lib\site-packages\flask\app.py", line 1614, in full_dispatch_request
    rv = self.handle_user_exception(e)
  File "d:\python2.7\lib\site-packages\flask\app.py", line 1517, in handle_user_exception
    reraise(exc_type, exc_value, tb)
  File "d:\python2.7\lib\site-packages\flask\app.py", line 1612, in full_dispatch_request
    rv = self.dispatch_request()
  File "d:\python2.7\lib\site-packages\flask\app.py", line 1598, in dispatch_request
    return self.view_functions[rule.endpoint](**req.view_args)
  File "d:\python2.7\lib\site-packages\flask_login.py", line 792, in decorated_view
    return func(*args, **kwargs)
  File "C:\Users\Wilson Wang\Desktop\Flask\microblog\app\routes.py", line 82, in edit_profile
    if form.validate_on_submit():
  File "d:\python2.7\lib\site-packages\flask_wtf\form.py", line 101, in validate_on_submit
    return self.is_submitted() and self.validate()
  File "d:\python2.7\lib\site-packages\wtforms\form.py", line 310, in validate
    return super(Form, self).validate(extra)
  File "d:\python2.7\lib\site-packages\wtforms\form.py", line 152, in validate
    if not field.validate(self, extra):
  File "d:\python2.7\lib\site-packages\wtforms\fields\core.py", line 204, in validate
    stop_validation = self._run_validation_chain(form, chain)
  File "d:\python2.7\lib\site-packages\wtforms\fields\core.py", line 224, in _run_validation_chain
    validator(form, self)
  File "C:\Users\Wilson Wang\Desktop\Flask\microblog\app\forms.py", line 41, in validate_username
    user = User.query.filter_by(username=self.Username.data).first()
AttributeError: 'EditProfileForm' object has no attribute 'Username'
2018-04-03 09:18:29,592 INFO: Microblog start up [in C:\Users\Wilson Wang\Desktop\Flask\microblog\app\__init__.py:43]
2018-04-03 14:55:58,088 INFO: Microblog start up [in C:\Users\Wilson Wang\Desktop\Flask\microblog\app\__init__.py:43]
2018-04-03 14:58:15,799 INFO: Microblog start up [in C:\Users\Wilson Wang\Desktop\Flask\microblog\app\__init__.py:43]
2018-04-03 14:59:22,184 INFO: Microblog start up [in C:\Users\Wilson Wang\Desktop\Flask\microblog\app\__init__.py:43]
2018-04-03 15:01:31,203 INFO: Microblog start up [in C:\Users\Wilson Wang\Desktop\Flask\microblog\app\__init__.py:43]
2018-04-03 15:02:44,369 INFO: Microblog start up [in C:\Users\Wilson Wang\Desktop\Flask\microblog\app\__init__.py:43]
2018-04-03 15:08:53,740 INFO: Microblog start up [in C:\Users\Wilson Wang\Desktop\Flask\microblog\app\__init__.py:43]
2018-04-03 15:09:33,109 INFO: Microblog start up [in C:\Users\Wilson Wang\Desktop\Flask\microblog\app\__init__.py:43]
2018-04-03 15:09:59,052 INFO: Microblog start up [in C:\Users\Wilson Wang\Desktop\Flask\microblog\app\__init__.py:43]
2018-04-03 15:49:13,756 INFO: Microblog start up [in C:\Users\Wilson Wang\Desktop\Flask\microblog\app\__init__.py:43]
2018-04-03 15:50:02,696 INFO: Microblog start up [in C:\Users\Wilson Wang\Desktop\Flask\microblog\app\__init__.py:43]
2018-04-03 15:50:27,934 INFO: Microblog start up [in C:\Users\Wilson Wang\Desktop\Flask\microblog\app\__init__.py:43]
2018-04-03 16:02:51,210 INFO: Microblog start up [in C:\Users\Wilson Wang\Desktop\Flask\microblog\app\__init__.py:43]
2018-04-03 16:06:06,713 INFO: Microblog start up [in C:\Users\Wilson Wang\Desktop\Flask\microblog\app\__init__.py:43]
2018-04-03 16:07:17,812 INFO: Microblog start up [in C:\Users\Wilson Wang\Desktop\Flask\microblog\app\__init__.py:43]
2018-04-03 16:07:32,392 INFO: Microblog start up [in C:\Users\Wilson Wang\Desktop\Flask\microblog\app\__init__.py:43]
2018-04-03 16:08:31,148 INFO: Microblog start up [in C:\Users\Wilson Wang\Desktop\Flask\microblog\app\__init__.py:43]
2018-04-03 16:10:00,068 INFO: Microblog start up [in C:\Users\Wilson Wang\Desktop\Flask\microblog\app\__init__.py:43]
2018-04-03 16:10:39,588 INFO: Microblog start up [in C:\Users\Wilson Wang\Desktop\Flask\microblog\app\__init__.py:43]
2018-04-03 16:19:55,361 INFO: Microblog start up [in C:\Users\Wilson Wang\Desktop\Flask\microblog\app\__init__.py:43]
2018-04-03 16:22:56,581 ERROR: Exception on /follow/Akie [GET] [in d:\python2.7\lib\site-packages\flask\app.py:1560]
Traceback (most recent call last):
  File "d:\python2.7\lib\site-packages\flask\app.py", line 1982, in wsgi_app
    response = self.full_dispatch_request()
  File "d:\python2.7\lib\site-packages\flask\app.py", line 1614, in full_dispatch_request
    rv = self.handle_user_exception(e)
  File "d:\python2.7\lib\site-packages\flask\app.py", line 1517, in handle_user_exception
    reraise(exc_type, exc_value, tb)
  File "d:\python2.7\lib\site-packages\flask\app.py", line 1612, in full_dispatch_request
    rv = self.dispatch_request()
  File "d:\python2.7\lib\site-packages\flask\app.py", line 1598, in dispatch_request
    return self.view_functions[rule.endpoint](**req.view_args)
  File "d:\python2.7\lib\site-packages\flask_login.py", line 792, in decorated_view
    return func(*args, **kwargs)
  File "C:\Users\Wilson Wang\Desktop\Flask\microblog\app\routes.py", line 96, in follow
    user = User.query.filter_by(usrename=username).first()
  File "d:\python2.7\lib\site-packages\sqlalchemy\orm\query.py", line 1596, in filter_by
    for key, value in kwargs.items()]
  File "d:\python2.7\lib\site-packages\sqlalchemy\orm\base.py", line 383, in _entity_descriptor
    (description, key)
InvalidRequestError: Entity '<class 'app.models.User'>' has no property 'usrename'
2018-04-03 16:23:47,082 INFO: Microblog start up [in C:\Users\Wilson Wang\Desktop\Flask\microblog\app\__init__.py:43]
