2018-04-03 16:23:56,234 ERROR: Exception on /follow/Akie [GET] [in d:\python2.7\lib\site-packages\flask\app.py:1560]
Traceback (most recent call last):
  File "d:\python2.7\lib\site-packages\flask\app.py", line 1982, in wsgi_app
    response = self.full_dispatch_request()
  File "d:\python2.7\lib\site-packages\flask\app.py", line 1614, in full_dispatch_request
    rv = self.handle_user_exception(e)
  File "d:\python2.7\lib\site-packages\flask\app.py", line 1517, in handle_user_exception
    reraise(exc_type, exc_value, tb)
  File "d:\python2.7\lib\site-packages\flask\app.py", line 1612, in full_dispatch_request
    rv = self.dispatch_request()
  File "d:\python2.7\lib\site-packages\flask\app.py", line 1598, in dispatch_request
    return self.view_functions[rule.endpoint](**req.view_args)
  File "d:\python2.7\lib\site-packages\flask_login.py", line 792, in decorated_view
    return func(*args, **kwargs)
  File "C:\Users\Wilson Wang\Desktop\Flask\microblog\app\routes.py", line 106, in follow
    return redirect(url_for('user', usrename=username))
  File "d:\python2.7\lib\site-packages\flask\helpers.py", line 333, in url_for
    return appctx.app.handle_url_build_error(error, endpoint, values)
  File "d:\python2.7\lib\site-packages\flask\app.py", line 1805, in handle_url_build_error
    reraise(exc_type, exc_value, tb)
  File "d:\python2.7\lib\site-packages\flask\helpers.py", line 323, in url_for
    force_external=external)
  File "d:\python2.7\lib\site-packages\werkzeug\routing.py", line 1776, in build
    raise BuildError(endpoint, values, method, self)
BuildError: Could not build url for endpoint 'user' with values ['usrename']. Did you forget to specify values ['username']?
2018-04-03 16:24:23,789 INFO: Microblog start up [in C:\Users\Wilson Wang\Desktop\Flask\microblog\app\__init__.py:43]
2018-04-03 16:24:35,908 ERROR: Exception on /unfollow/Akie [GET] [in d:\python2.7\lib\site-packages\flask\app.py:1560]
Traceback (most recent call last):
  File "d:\python2.7\lib\site-packages\flask\app.py", line 1982, in wsgi_app
    response = self.full_dispatch_request()
  File "d:\python2.7\lib\site-packages\flask\app.py", line 1614, in full_dispatch_request
    rv = self.handle_user_exception(e)
  File "d:\python2.7\lib\site-packages\flask\app.py", line 1517, in handle_user_exception
    reraise(exc_type, exc_value, tb)
  File "d:\python2.7\lib\site-packages\flask\app.py", line 1612, in full_dispatch_request
    rv = self.dispatch_request()
  File "d:\python2.7\lib\site-packages\flask\app.py", line 1598, in dispatch_request
    return self.view_functions[rule.endpoint](**req.view_args)
  File "d:\python2.7\lib\site-packages\flask_login.py", line 792, in decorated_view
    return func(*args, **kwargs)
  File "C:\Users\Wilson Wang\Desktop\Flask\microblog\app\routes.py", line 111, in unfollow
    user = User.query.filter_by(usrename=username).first()
  File "d:\python2.7\lib\site-packages\sqlalchemy\orm\query.py", line 1596, in filter_by
    for key, value in kwargs.items()]
  File "d:\python2.7\lib\site-packages\sqlalchemy\orm\base.py", line 383, in _entity_descriptor
    (description, key)
InvalidRequestError: Entity '<class 'app.models.User'>' has no property 'usrename'
2018-04-03 16:25:08,437 INFO: Microblog start up [in C:\Users\Wilson Wang\Desktop\Flask\microblog\app\__init__.py:43]
2018-04-03 17:13:53,877 INFO: Microblog start up [in C:\Users\Wilson Wang\Desktop\Flask\microblog\app\__init__.py:43]
2018-04-03 17:14:12,039 ERROR: Exception on /index [GET] [in d:\python2.7\lib\site-packages\flask\app.py:1560]
Traceback (most recent call last):
  File "d:\python2.7\lib\site-packages\flask\app.py", line 1982, in wsgi_app
    response = self.full_dispatch_request()
  File "d:\python2.7\lib\site-packages\flask\app.py", line 1614, in full_dispatch_request
    rv = self.handle_user_exception(e)
  File "d:\python2.7\lib\site-packages\flask\app.py", line 1517, in handle_user_exception
    reraise(exc_type, exc_value, tb)
  File "d:\python2.7\lib\site-packages\flask\app.py", line 1612, in full_dispatch_request
    rv = self.dispatch_request()
  File "d:\python2.7\lib\site-packages\flask\app.py", line 1598, in dispatch_request
    return self.view_functions[rule.endpoint](**req.view_args)
  File "d:\python2.7\lib\site-packages\flask_login.py", line 792, in decorated_view
    return func(*args, **kwargs)
  File "C:\Users\Wilson Wang\Desktop\Flask\microblog\app\routes.py", line 36, in index
    posts = current_user.followed_posts.all()
AttributeError: 'function' object has no attribute 'all'
2018-04-03 17:15:53,398 INFO: Microblog start up [in C:\Users\Wilson Wang\Desktop\Flask\microblog\app\__init__.py:43]
2018-04-03 17:17:25,061 INFO: Microblog start up [in C:\Users\Wilson Wang\Desktop\Flask\microblog\app\__init__.py:43]
2018-04-03 21:42:36,809 INFO: Microblog start up [in C:\Users\Wilson Wang\Desktop\Flask\microblog\app\__init__.py:43]
2018-04-03 22:16:35,091 INFO: Microblog start up [in C:\Users\Wilson Wang\Desktop\Flask\microblog\app\__init__.py:43]
2018-04-04 09:35:03,483 INFO: Microblog start up [in C:\Users\Wilson Wang\Desktop\Flask\microblog\app\__init__.py:45]
2018-04-04 09:35:25,341 ERROR: Exception on /reset_password_request [POST] [in d:\python2.7\lib\site-packages\flask\app.py:1560]
Traceback (most recent call last):
  File "d:\python2.7\lib\site-packages\flask\app.py", line 1982, in wsgi_app
    response = self.full_dispatch_request()
  File "d:\python2.7\lib\site-packages\flask\app.py", line 1614, in full_dispatch_request
    rv = self.handle_user_exception(e)
  File "d:\python2.7\lib\site-packages\flask\app.py", line 1517, in handle_user_exception
    reraise(exc_type, exc_value, tb)
  File "d:\python2.7\lib\site-packages\flask\app.py", line 1612, in full_dispatch_request
    rv = self.dispatch_request()
  File "d:\python2.7\lib\site-packages\flask\app.py", line 1598, in dispatch_request
    return self.view_functions[rule.endpoint](**req.view_args)
  File "C:\Users\Wilson Wang\Desktop\Flask\microblog\app\routes.py", line 155, in reset_password_request
    send_password_reset_email(user)
  File "C:\Users\Wilson Wang\Desktop\Flask\microblog\app\email.py", line 12, in send_password_reset_email
    token = user.get_reset_password_token()
  File "C:\Users\Wilson Wang\Desktop\Flask\microblog\app\models.py", line 66, in get_reset_password_token
    return jwt.encode(
NameError: global name 'jwt' is not defined
2018-04-04 09:37:06,858 INFO: Microblog start up [in C:\Users\Wilson Wang\Desktop\Flask\microblog\app\__init__.py:45]
2018-04-04 09:37:18,582 ERROR: Exception on /reset_password_request [POST] [in d:\python2.7\lib\site-packages\flask\app.py:1560]
Traceback (most recent call last):
  File "d:\python2.7\lib\site-packages\flask\app.py", line 1982, in wsgi_app
    response = self.full_dispatch_request()
  File "d:\python2.7\lib\site-packages\flask\app.py", line 1614, in full_dispatch_request
    rv = self.handle_user_exception(e)
  File "d:\python2.7\lib\site-packages\flask\app.py", line 1517, in handle_user_exception
    reraise(exc_type, exc_value, tb)
  File "d:\python2.7\lib\site-packages\flask\app.py", line 1612, in full_dispatch_request
    rv = self.dispatch_request()
  File "d:\python2.7\lib\site-packages\flask\app.py", line 1598, in dispatch_request
    return self.view_functions[rule.endpoint](**req.view_args)
  File "C:\Users\Wilson Wang\Desktop\Flask\microblog\app\routes.py", line 155, in reset_password_request
    send_password_reset_email(user)
  File "C:\Users\Wilson Wang\Desktop\Flask\microblog\app\email.py", line 19, in send_password_reset_email
    user=user, token=token))
  File "C:\Users\Wilson Wang\Desktop\Flask\microblog\app\email.py", line 7, in send_email
    mes.body = text_body
NameError: global name 'mes' is not defined
2018-04-04 09:37:54,118 INFO: Microblog start up [in C:\Users\Wilson Wang\Desktop\Flask\microblog\app\__init__.py:45]
2018-04-04 09:38:42,903 INFO: Microblog start up [in C:\Users\Wilson Wang\Desktop\Flask\microblog\app\__init__.py:45]
2018-04-04 09:39:30,911 ERROR: Exception on /reset_password/eyJhbGciOiJIUzI1NiIsInR5cCI6IkpXVCJ9.eyJyZXNldF9wYXNzd29yZCI6MywiZXhwIjoxNTIyODA2NTMyLjk5Mn0.4mEG9Py9nFM2xNOddFvk6bXZ3hHeufaIE4_M37sJeQc [GET] [in d:\python2.7\lib\site-packages\flask\app.py:1560]
Traceback (most recent call last):
  File "d:\python2.7\lib\site-packages\flask\app.py", line 1982, in wsgi_app
    response = self.full_dispatch_request()
  File "d:\python2.7\lib\site-packages\flask\app.py", line 1614, in full_dispatch_request
    rv = self.handle_user_exception(e)
  File "d:\python2.7\lib\site-packages\flask\app.py", line 1517, in handle_user_exception
    reraise(exc_type, exc_value, tb)
  File "d:\python2.7\lib\site-packages\flask\app.py", line 1612, in full_dispatch_request
    rv = self.dispatch_request()
  File "d:\python2.7\lib\site-packages\flask\app.py", line 1598, in dispatch_request
    return self.view_functions[rule.endpoint](**req.view_args)
  File "C:\Users\Wilson Wang\Desktop\Flask\microblog\app\routes.py", line 167, in reset_password
    form = ResetPasswordForm()
NameError: global name 'ResetPasswordForm' is not defined
2018-04-04 09:41:22,265 INFO: Microblog start up [in C:\Users\Wilson Wang\Desktop\Flask\microblog\app\__init__.py:45]
2018-04-04 10:27:28,835 INFO: Microblog start up [in C:\Users\Wilson Wang\Desktop\Flask\microblog\app\__init__.py:47]
2018-04-04 10:29:47,818 INFO: Microblog start up [in C:\Users\Wilson Wang\Desktop\Flask\microblog\app\__init__.py:47]
2018-04-04 10:32:46,456 INFO: Microblog start up [in C:\Users\Wilson Wang\Desktop\Flask\microblog\app\__init__.py:47]
2018-04-04 11:20:24,628 INFO: Microblog start up [in C:\Users\Wilson Wang\Desktop\Flask\microblog\app\__init__.py:49]
2018-04-04 11:22:52,727 INFO: Microblog start up [in C:\Users\Wilson Wang\Desktop\Flask\microblog\app\__init__.py:49]
2018-04-04 11:25:44,575 INFO: Microblog start up [in C:\Users\Wilson Wang\Desktop\Flask\microblog\app\__init__.py:49]
2018-04-04 11:28:22,595 INFO: Microblog start up [in C:\Users\Wilson Wang\Desktop\Flask\microblog\app\__init__.py:49]
